<?xml version="1.0"?>
<robot xmlns:xacro="http://www.ros.org/wiki/xacro" >

        <xacro:include filename="inertial_macros.xacro"/>
    

            <!-- Farben -->

    <material name="white">
        <color rgba="1 1 1 1"/>
    </material>

    <material name="black">
        <color rgba="0 0 0 1"/>
    </material>

    <material name="blue">
        <color rgba="0.2 0.2 1 1"/>
    </material>

    <material name="yellow">
        <color rgba="1 1 0 1"/>
    </material>

    <material name="orange">
        <color rgba="1 0.3 0.1 1"/>
    </material>

    <material name="green">
        <color rgba="0.0 1.0 0.0 1.0"/>
    </material>

    <!-- BASE LINK -->

    <link name="base_link">
        
    </link>
    <!-- CHASSIS LINK -->
    <joint name="cassis_joint" type="fixed">
        <parent link="base_link"/>
        <child link="chassis"/>
        <origin xyz="-0.093 0.0 0.0"/>
        
    </joint>


    <link name="chassis">
        <visual>
            <origin xyz="0.093 0.0 0.02"/>
            <geometry>
                <cylinder radius="0.093" length="0.045"/>
            </geometry>
            <material name="orange"/>
        </visual>
        <collision>
            <origin xyz="0.093 0.0 0.075"/>
            <geometry>
                <cylinder radius="0.093" length="0.045"/>
            </geometry>            
        </collision>
        <xacro:inertial_cylinder mass="0.5" length="0.045" radius="0.093">
            <origin xyz="0.0 0.0 0.0" rpy="0.0 0.0 0.0"/>
        </xacro:inertial_cylinder>
    </link>

    <gazebo reference="chassis">
        <material>Gazebo/Orange</material>
    </gazebo>

        <!-- LEFT WHEEL LINK -->

    <joint name="left_wheel_joint" type="continuous">
        <origin xyz="0.0 0.11 0.0" rpy="-${pi/2} 0.0 0.0"/>
        <parent link="base_link"/>
        <child link="left_wheel"/>
        <axis xyz="0.0 0.0 1.0"/>
        <limit lower="0.0" upper="0.0" effort="0.0" velocity="0.0"/>
    </joint>

    <link name="left_wheel">
        <visual>
            <geometry>
                <cylinder radius="0.035" length="0.028"/>
            </geometry>
            <material name="blue"/>               
        </visual>
        <collision>
            <geometry>
                <cylinder radius="0.035" length="0.028"/>
            </geometry>               
        </collision>
        <xacro:inertial_cylinder mass="0.1" length="0.028" radius="0.035">
            <origin xyz="0.0 0.0 0.0" rpy="0.0 0.0 0.0"/>
        </xacro:inertial_cylinder>
    </link>

    <gazebo reference="left_wheel">
        <material>Gazebo/Blue</material>
    </gazebo>
    
    <!-- RIGHT WHEEL LINK -->
    <joint name="right_wheel_joint" type="continuous">
        <origin xyz="0.0 -0.11 0.0" rpy="${pi/2} 0.0 0.0"/>
        <parent link="base_link"/>
        <child link="right_wheel"/>
        <axis xyz="0.0 0.0 -1.0"/>
        <limit lower="0.0" upper="0.0" effort="0.0" velocity="0.0"/>
    </joint>

    <link name="right_wheel">
        <visual>
            <geometry>
                <cylinder radius="0.035" length="0.028"/>
            </geometry>
            <material name="blue"/>               
        </visual>
        <collision>
            <geometry>
                <cylinder radius="0.035" length="0.028"/>
            </geometry>               
        </collision>
        <xacro:inertial_cylinder mass="0.1" length="0.028" radius="0.035">
            <origin xyz="0.0 0.0 0.0" rpy="0.0 0.0 0.0"/>
        </xacro:inertial_cylinder>
    </link>

    <gazebo reference="right_wheel">
        <material>Gazebo/Blue</material>
    </gazebo>


    <!-- CASTER WHEEL FRONT LINK -->

    <joint name="caster_wheel_front_joint" type="fixed">
        <parent link="base_link"/>
        <child link="caster_wheel_front"/>
        <origin xyz="0.085 0.0 -0.016"/>        
    </joint>

    <link name="caster_wheel_front">
        <visual>
            <geometry>
                <sphere radius="0.018"/>
            </geometry>
            <material name="black"/>
        </visual>
        <collision>
            <geometry>
                <sphere radius="0.018"/>
            </geometry>
        </collision>
        <xacro:inertial_sphere mass="0.3" radius="0.018">
            <origin xyz="0.0 0.0 0.0" rpy="0.0 0.0 0.0"/>
        </xacro:inertial_sphere>
    </link>

    <gazebo reference="caster_wheel_front">
        <material>Gazebo/Black</material>
        <mu1 value="0.001"/>
        <mu2 value="0.001"/>
    </gazebo>

    <!-- CASTER WHEEL REAR LINK -->

    <joint name="caster_wheel_rear_joint" type="fixed">
        <parent link="base_link"/>
        <child link="caster_wheel_rear"/>
        <origin xyz="-0.085 0.0 -0.0165"/>        
    </joint>

    <link name="caster_wheel_rear">
        <visual>
            <geometry>
                <sphere radius="0.018"/>
            </geometry>
            <material name="black"/>
        </visual>
        <collision>
            <geometry>
                <sphere radius="0.018"/>
            </geometry>
        </collision>
        <xacro:inertial_sphere mass="0.3" radius="0.018">
            <origin xyz="0.0 0.0 0.0" rpy="0.0 0.0 0.0"/>
        </xacro:inertial_sphere>
    </link>

    <gazebo reference="caster_wheel_rear">
        <material>Gazebo/Black</material>
        <mu1 value="0.001"/>
        <mu2 value="0.001"/>
    </gazebo>

    <!-- Body Part -->

    <link name="body">
        <visual>
            <geometry>
                <cylinder radius="0.11" length="0.345"/>
            </geometry>
            <material name="yellow"/>
        </visual>
        <collision>
            <geometry>
                <cylinder radius="0.11" length="0.345"/>
            </geometry>
        </collision>
        <xacro:inertial_cylinder mass="0.1" length="0.345" radius="0.11">
            <origin xyz="0.0 0.0 0.0" rpy="0.0 0.0 0.0"/>
        </xacro:inertial_cylinder>       
    </link>

    <gazebo reference="body">
        <material>Gazebo/Yellow</material>
    </gazebo>

    <joint name="body_joint" type="fixed">
        <parent link="base_link"/>
        <child link="body"/>
        <origin xyz="0.0 0.0 0.21"/>        
    </joint>
    
    <!-- LCD DISPLAY and In_display  -->

    <link name="display">
        <visual>
            <geometry>
                <box size="0.09 0.09 0.05"/>
            </geometry>
            <material name="black"/>
        </visual>
        <collision>
            <geometry>
                <box size="0.09 0.09 0.03"/>
            </geometry>            
        </collision>
        <xacro:inertial_box mass="0.1" x="0.09" y="0.09" z="0.05">
            <origion xyz="0.0 0.0 0.0" rpy="0.0 0.0 0.0"/>
        </xacro:inertial_box> 
    </link>

    <gazebo reference="display">
        <material>Gazebo/Black</material>
    </gazebo>

    <joint name="display_body_joint" type="fixed">
        <origin xyz="0.08 0.0 0.11" rpy="0 0.0 0.0"/>
        <parent link="body"/>
        <child link="display"/>
    </joint>

    <link name="in_display">
        <visual>
            <geometry>
                <box size="0.09 0.07 0.03"/>
            </geometry>
            <material name="green"/>
        </visual>
        <collision>
            <geometry>
                <box size="0.09 0.07 0.03"/>
            </geometry>            
        </collision>
        <xacro:inertial_box mass="0.1" x="0.09" y="0.09" z="0.03">
            <origion xyz="0.0 0.0 0.0" rpy="0.0 0.0 0.0"/>
        </xacro:inertial_box> 
    </link>

    <gazebo reference="in_display">
        <material>Gazebo/Green</material>
    </gazebo>

    <joint name="in_display_body_joint" type="fixed">
        <origin xyz="0.085 0.0 0.11" rpy="0 0.0 0.0"/>
        <parent link="body"/>
        <child link="in_display"/>
    </joint>


</robot>